Workbook
Name HR_RAW_DATA: 'Raw Data'!$A$1:$M$51
Name Slicer_City: #N/A
Name Slicer_Department: #N/A
Name Slicer_Gender: #N/A

Sheet Raw Data
A1: EmpID | B1: Name | C1: Gender | D1: Age | E1: Department | F1: JoinDate | G1: ExitDate | H1: Salary | I1: Experience | J1: City | K1: Status | L1: Join Year | M1: Experience Band
A2: E001 | B2: Rahul | C2: Male | D2: 28 | E2: Sales | F2: 44168 | H2: 45000 | I2: 4 | J2: Delhi | K2: =IF(G2="","Active","Exited") -> Active | L2: 2020 | M2: {=_xlfn.IFS(I2<=3,"0-3 Years",I2<=8,"4-8 Years",I2<=15,"9-15 Years",I2>15,"15+ Years")} -> 4-8 Years
A3: E002 | B3: Priya | C3: Female | D3: 32 | E3: HR | F3: 18/07/2019 | H3: 52000 | I3: 7 | J3: Mumbai | K3: =IF(G3="","Active","Exited") -> Active | L3: 2019 | M3: {=_xlfn.IFS(I3<=3,"0-3 Years",I3<=8,"4-8 Years",I3<=15,"9-15 Years",I3>15,"15+ Years")} -> 4-8 Years
A4: E003 | B4: Amit | C4: Male | D4: 45 | E4: Finance | F4: 42036 | G4: 15/09/2023 | H4: 90000 | I4: 18 | J4: Pune | K4: =IF(G4="","Active","Exited") -> Exited | L4: 2015 | M4: {=_xlfn.IFS(I4<=3,"0-3 Years",I4<=8,"4-8 Years",I4<=15,"9-15 Years",I4>15,"15+ Years")} -> 15+ Years
A5: E004 | B5: Neha | C5: Female | D5: 26 | E5: IT | F5: 44475 | H5: 48000 | I5: 2 | J5: Bengaluru | K5: =IF(G5="","Active","Exited") -> Active | L5: 2021 | M5: {=_xlfn.IFS(I5<=3,"0-3 Years",I5<=8,"4-8 Years",I5<=15,"9-15 Years",I5>15,"15+ Years")} -> 0-3 Years
A6: E005 | B6: Karan | C6: Male | D6: 39 | E6: Operations | F6: 42866 | H6: 65000 | I6: 12 | J6: Chennai | K6: =IF(G6="","Active","Exited") -> Active | L6: 2017 | M6: {=_xlfn.IFS(I6<=3,"0-3 Years",I6<=8,"4-8 Years",I6<=15,"9-15 Years",I6>15,"15+ Years")} -> 9-15 Years
A7: E006 | B7: Sneha | C7: Female | D7: 29 | E7: Marketing | F7: 20/08/2020 | H7: 47000 | I7: 5 | J7: Delhi | K7: =IF(G7="","Active","Exited") -> Active | L7: 2020 | M7: {=_xlfn.IFS(I7<=3,"0-3 Years",I7<=8,"4-8 Years",I7<=15,"9-15 Years",I7>15,"15+ Years")} -> 4-8 Years
A8: E007 | B8: Arjun | C8: Male | D8: 34 | E8: Sales | F8: 15/04/2018 | H8: 60000 | I8: 9 | J8: Jaipur | K8: =IF(G8="","Active","Exited") -> Active | L8: 2018 | M8: {=_xlfn.IFS(I8<=3,"0-3 Years",I8<=8,"4-8 Years",I8<=15,"9-15 Years",I8>15,"15+ Years")} -> 9-15 Years
A9: E008 | B9: Pooja | C9: Female | D9: 41 | E9: Finance | F9: 41641 | H9: 85000 | I9: 15 | J9: Mumbai | K9: =IF(G9="","Active","Exited") -> Active | L9: 2014 | M9: {=_xlfn.IFS(I9<=3,"0-3 Years",I9<=8,"4-8 Years",I9<=15,"9-15 Years",I9>15,"15+ Years")} -> 9-15 Years
A10: E009 | B10: Vikram | C10: Male | D10: 31 | E10: IT | F10: 43717 | H10: 55000 | I10: 6 | J10: Hyderabad | K10: =IF(G10="","Active","Exited") -> Active | L10: 2019 | M10: {=_xlfn.IFS(I10<=3,"0-3 Years",I10<=8,"4-8 Years",I10<=15,"9-15 Years",I10>15,"15+ Years")} -> 4-8 Years
A11: E010 | B11: Ritu | C11: Female | D11: 27 | E11: HR | F11: 44866 | H11: 42000 | I11: 2 | J11: Noida | K11: =IF(G11="","Active","Exited") -> Active | L11: 2022 | M11: {=_xlfn.IFS(I11<=3,"0-3 Years",I11<=8,"4-8 Years",I11<=15,"9-15 Years",I11>15,"15+ Years")} -> 0-3 Years
A12: E011 | B12: Suresh | C12: Male | D12: 50 | E12: Operations | F12: 25/05/2010 | G12: 44907 | H12: 110000 | I12: 25 | J12: Chennai | K12: =IF(G12="","Active","Exited") -> Exited | L12: 2010 | M12: {=_xlfn.IFS(I12<=3,"0-3 Years",I12<=8,"4-8 Years",I12<=15,"9-15 Years",I12>15,"15+ Years")} -> 15+ Years
A13: E012 | B13: Anjali | C13: Female | D13: 36 | E13: Marketing | F13: 17/03/2016 | H13: 72000 | I13: 11 | J13: Pune | K13: =IF(G13="","Active","Exited") -> Active | L13: 2016 | M13: {=_xlfn.IFS(I13<=3,"0-3 Years",I13<=8,"4-8 Years",I13<=15,"9-15 Years",I13>15,"15+ Years")} -> 9-15 Years
A14: E013 | B14: Rohit | C14: Male | D14: 24 | E14: IT | F14: 44933 | H14: 35000 | I14: 1 | J14: Bengaluru | K14: =IF(G14="","Active","Exited") -> Active | L14: 2023 | M14: {=_xlfn.IFS(I14<=3,"0-3 Years",I14<=8,"4-8 Years",I14<=15,"9-15 Years",I14>15,"15+ Years")} -> 0-3 Years
A15: E014 | B15: Simran | C15: Female | D15: 30 | E15: Sales | F15: 21/10/2019 | H15: 58000 | I15: 6 | J15: Amritsar | K15: =IF(G15="","Active","Exited") -> Active | L15: 2019 | M15: {=_xlfn.IFS(I15<=3,"0-3 Years",I15<=8,"4-8 Years",I15<=15,"9-15 Years",I15>15,"15+ Years")} -> 4-8 Years
A16: E015 | B16: Deepak | C16: Male | D16: 42 | E16: Finance | F16: 14/12/2012 | H16: 95000 | I16: 20 | J16: Delhi | K16: =IF(G16="","Active","Exited") -> Active | L16: 2012 | M16: {=_xlfn.IFS(I16<=3,"0-3 Years",I16<=8,"4-8 Years",I16<=15,"9-15 Years",I16>15,"15+ Years")} -> 15+ Years
A17: E016 | B17: Kavita | C17: Female | D17: 35 | E17: HR | F17: 19/06/2017 | H17: 62000 | I17: 10 | J17: Jaipur | K17: =IF(G17="","Active","Exited") -> Active | L17: 2017 | M17: {=_xlfn.IFS(I17<=3,"0-3 Years",I17<=8,"4-8 Years",I17<=15,"9-15 Years",I17>15,"15+ Years")} -> 9-15 Years
A18: E017 | B18: Manoj | C18: Male | D18: 29 | E18: Operations | F18: 44410 | H18: 50000 | I18: 4 | J18: Indore | K18: =IF(G18="","Active","Exited") -> Active | L18: 2021 | M18: {=_xlfn.IFS(I18<=3,"0-3 Years",I18<=8,"4-8 Years",I18<=15,"9-15 Years",I18>15,"15+ Years")} -> 4-8 Years
A19: E018 | B19: Rina | C19: Female | D19: 38 | E19: Marketing | F19: 27/09/2015 | H19: 78000 | I19: 13 | J19: Kolkata | K19: =IF(G19="","Active","Exited") -> Active | L19: 2015 | M19: {=_xlfn.IFS(I19<=3,"0-3 Years",I19<=8,"4-8 Years",I19<=15,"9-15 Years",I19>15,"15+ Years")} -> 9-15 Years
A20: E019 | B20: Nitin | C20: Male | D20: 33 | E20: IT | F20: 43527 | H20: 61000 | I20: 7 | J20: Gurgaon | K20: =IF(G20="","Active","Exited") -> Active | L20: 2019 | M20: {=_xlfn.IFS(I20<=3,"0-3 Years",I20<=8,"4-8 Years",I20<=15,"9-15 Years",I20>15,"15+ Years")} -> 4-8 Years
A21: E020 | B21: Shalini | C21: Female | D21: 46 | E21: Sales | F21: 40858 | G21: 30/06/2023 | H21: 88000 | I21: 21 | J21: Mumbai | K21: =IF(G21="","Active","Exited") -> Exited | L21: 2011 | M21: {=_xlfn.IFS(I21<=3,"0-3 Years",I21<=8,"4-8 Years",I21<=15,"9-15 Years",I21>15,"15+ Years")} -> 15+ Years
A22: E021 | B22: Akash | C22: Male | D22: 27 | E22: Marketing | F22: 44686 | H22: 41000 | I22: 2 | J22: Delhi | K22: =IF(G22="","Active","Exited") -> Active | L22: 2022 | M22: {=_xlfn.IFS(I22<=3,"0-3 Years",I22<=8,"4-8 Years",I22<=15,"9-15 Years",I22>15,"15+ Years")} -> 0-3 Years
A23: E022 | B23: Pallavi | C23: Female | D23: 34 | E23: Finance | F23: 14/08/2018 | H23: 70000 | I23: 9 | J23: Pune | K23: =IF(G23="","Active","Exited") -> Active | L23: 2018 | M23: {=_xlfn.IFS(I23<=3,"0-3 Years",I23<=8,"4-8 Years",I23<=15,"9-15 Years",I23>15,"15+ Years")} -> 9-15 Years
A24: E023 | B24: Raj | C24: Male | D24: 40 | E24: Operations | F24: 41891 | H24: 68000 | I24: 15 | J24: Nagpur | K24: =IF(G24="","Active","Exited") -> Active | L24: 2014 | M24: {=_xlfn.IFS(I24<=3,"0-3 Years",I24<=8,"4-8 Years",I24<=15,"9-15 Years",I24>15,"15+ Years")} -> 9-15 Years
A25: E024 | B25: Tanya | C25: Female | D25: 31 | E25: IT | F25: 23/01/2020 | H25: 59000 | I25: 6 | J25: Noida | K25: =IF(G25="","Active","Exited") -> Active | L25: 2020 | M25: {=_xlfn.IFS(I25<=3,"0-3 Years",I25<=8,"4-8 Years",I25<=15,"9-15 Years",I25>15,"15+ Years")} -> 4-8 Years
A26: E025 | B26: Sanjay | C26: Male | D26: 48 | E26: HR | F26: 17/06/2010 | G26: 28/02/2022 | H26: 82000 | I26: 22 | J26: Bhopal | K26: =IF(G26="","Active","Exited") -> Exited | L26: 2010 | M26: {=_xlfn.IFS(I26<=3,"0-3 Years",I26<=8,"4-8 Years",I26<=15,"9-15 Years",I26>15,"15+ Years")} -> 15+ Years
A27: E026 | B27: Meena | C27: Female | D27: 29 | E27: Sales | F27: 44290 | H27: 46000 | I27: 3 | J27: Surat | K27: =IF(G27="","Active","Exited") -> Active | L27: 2021 | M27: {=_xlfn.IFS(I27<=3,"0-3 Years",I27<=8,"4-8 Years",I27<=15,"9-15 Years",I27>15,"15+ Years")} -> 0-3 Years
A28: E027 | B28: Vivek | C28: Male | D28: 36 | E28: Finance | F28: 42684 | H28: 88000 | I28: 11 | J28: Indore | K28: =IF(G28="","Active","Exited") -> Active | L28: 2016 | M28: {=_xlfn.IFS(I28<=3,"0-3 Years",I28<=8,"4-8 Years",I28<=15,"9-15 Years",I28>15,"15+ Years")} -> 9-15 Years
A29: E028 | B29: Priyanshi | C29: Female | D29: 25 | E29: Marketing | F29: 15/12/2022 | H29: 36000 | I29: 1 | J29: Jaipur | K29: =IF(G29="","Active","Exited") -> Active | L29: 2022 | M29: {=_xlfn.IFS(I29<=3,"0-3 Years",I29<=8,"4-8 Years",I29<=15,"9-15 Years",I29>15,"15+ Years")} -> 0-3 Years
A30: E029 | B30: Ajay | C30: Male | D30: 44 | E30: IT | F30: 19/07/2013 | H30: 92000 | I30: 17 | J30: Pune | K30: =IF(G30="","Active","Exited") -> Active | L30: 2013 | M30: {=_xlfn.IFS(I30<=3,"0-3 Years",I30<=8,"4-8 Years",I30<=15,"9-15 Years",I30>15,"15+ Years")} -> 15+ Years
A31: E030 | B31: Nisha | C31: Female | D31: 37 | E31: Operations | F31: 42402 | H31: 73000 | I31: 12 | J31: Chandigarh | K31: =IF(G31="","Active","Exited") -> Active | L31: 2016 | M31: {=_xlfn.IFS(I31<=3,"0-3 Years",I31<=8,"4-8 Years",I31<=15,"9-15 Years",I31>15,"15+ Years")} -> 9-15 Years
A32: E031 | B32: Rakesh | C32: Male | D32: 52 | E32: Sales | F32: 39448 | G32: 31/03/2021 | H32: 105000 | I32: 28 | J32: Delhi | K32: =IF(G32="","Active","Exited") -> Exited | L32: 2008 | M32: {=_xlfn.IFS(I32<=3,"0-3 Years",I32<=8,"4-8 Years",I32<=15,"9-15 Years",I32>15,"15+ Years")} -> 15+ Years
A33: E032 | B33: Isha | C33: Female | D33: 28 | E33: HR | F33: 44539 | H33: 48000 | I33: 3 | J33: Mumbai | K33: =IF(G33="","Active","Exited") -> Active | L33: 2021 | M33: {=_xlfn.IFS(I33<=3,"0-3 Years",I33<=8,"4-8 Years",I33<=15,"9-15 Years",I33>15,"15+ Years")} -> 0-3 Years
A34: E033 | B34: Manish | C34: Male | D34: 35 | E34: Marketing | F34: 42892 | H34: 64000 | I34: 8 | J34: Lucknow | K34: =IF(G34="","Active","Exited") -> Active | L34: 2017 | M34: {=_xlfn.IFS(I34<=3,"0-3 Years",I34<=8,"4-8 Years",I34<=15,"9-15 Years",I34>15,"15+ Years")} -> 4-8 Years
A35: E034 | B35: Payal | C35: Female | D35: 41 | E35: Finance | F35: 18/03/2012 | H35: 90000 | I35: 19 | J35: Ahmedabad | K35: =IF(G35="","Active","Exited") -> Active | L35: 2012 | M35: {=_xlfn.IFS(I35<=3,"0-3 Years",I35<=8,"4-8 Years",I35<=15,"9-15 Years",I35>15,"15+ Years")} -> 15+ Years
A36: E035 | B36: Ankit | C36: Male | D36: 26 | E36: IT | F36: 25/08/2022 | H36: 38000 | I36: 1 | J36: Bhopal | K36: =IF(G36="","Active","Exited") -> Active | L36: 2022 | M36: {=_xlfn.IFS(I36<=3,"0-3 Years",I36<=8,"4-8 Years",I36<=15,"9-15 Years",I36>15,"15+ Years")} -> 0-3 Years
A37: E036 | B37: Sonal | C37: Female | D37: 33 | E37: Sales | F37: 43719 | H37: 57000 | I37: 7 | J37: Pune | K37: =IF(G37="","Active","Exited") -> Active | L37: 2019 | M37: {=_xlfn.IFS(I37<=3,"0-3 Years",I37<=8,"4-8 Years",I37<=15,"9-15 Years",I37>15,"15+ Years")} -> 4-8 Years
A38: E037 | B38: Kuldeep | C38: Male | D38: 39 | E38: Operations | F38: 14/04/2015 | H38: 69000 | I38: 14 | J38: Jodhpur | K38: =IF(G38="","Active","Exited") -> Active | L38: 2015 | M38: {=_xlfn.IFS(I38<=3,"0-3 Years",I38<=8,"4-8 Years",I38<=15,"9-15 Years",I38>15,"15+ Years")} -> 9-15 Years
A39: E038 | B39: Rekha | C39: Female | D39: 47 | E39: HR | F39: 20/02/2011 | H39: 85000 | I39: 23 | J39: Delhi | K39: =IF(G39="","Active","Exited") -> Active | L39: 2011 | M39: {=_xlfn.IFS(I39<=3,"0-3 Years",I39<=8,"4-8 Years",I39<=15,"9-15 Years",I39>15,"15+ Years")} -> 15+ Years
A40: E039 | B40: Varun | C40: Male | D40: 30 | E40: Marketing | F40: 44019 | H40: 52000 | I40: 4 | J40: Noida | K40: =IF(G40="","Active","Exited") -> Active | L40: 2020 | M40: {=_xlfn.IFS(I40<=3,"0-3 Years",I40<=8,"4-8 Years",I40<=15,"9-15 Years",I40>15,"15+ Years")} -> 4-8 Years
...

Sheet KPI CAlCULATION
A1: Total Employees | B1: Active Employees | C1: Exited Employees | D1: Attrition % | E1: Average Salary | F1: Average Experience
A2: =COUNTA('Raw Data'!$A$2:$A$51) -> 50 | B2: =COUNTIF('Raw Data'!K:K,"Active") -> 45 | C2: =COUNTIF('Raw Data'!K:K,"Exited") -> 5 | D2: =C2/A2 -> 0.1 | E2: =AVERAGE('Raw Data'!H2:H51) -> 66280 | F2: =AVERAGE('Raw Data'!I2:I51)&" Years " -> 10.36 Years

Sheet Pivot Table Analysis
A1: Pivot 1 – Department Analysis | F1: Pivot 2 – Gender Distribution | I1: Pivot 3 – Experience Band | M1: Pivot 4 – City Wise Employees | P1: Pivot 5 – Join Year Trend (with Line Chart) | S1: Pivot 6 – Department Wise Attrition % | V1: Top 5 Highest Paid Employees | Y1: Average Experience | AB1: Department Wise Number of Emp. | AE1: Deparment Wise Salary
A4: Row Labels | B4: Number of Emp | C4: Average Salary | D4: Attrition Count | F4: Row Labels | G4: Count of EmpID | I4: Row Labels | J4: Number of Employees | K4: Average of Salary | M4: Row Labels | N4: Number of Emp | P4: Row Labels | Q4: Sum of Salary | S4: Row Labels | T4: Attrition % | V4: Row Labels | W4: Emp Salary | Y4: Row Labels | Z4: Average of Experience | AB4: Row Labels | AC4: Number of Emp. | AE4: Row Labels | AF4: Deparment Wise Salary
A5: Finance | B5: 8 | C5: 83000 | D5: 1 | F5: Female | G5: 25 | I5: 0-3 Years | J5: 11 | K5: 42818.182 | M5: Delhi | N5: 6 | P5: 2008 | Q5: 105000 | S5: Finance | T5: 0.2 | V5: Suresh | W5: 110000 | Y5: Finance | Z5: 14.125 | AB5: Finance | AC5: 8 | AE5: Finance | AF5: 664000
A6: HR | B6: 7 | C6: 61000 | D6: 1 | F6: Male | G6: 25 | I6: 15+ Years | J6: 12 | K6: 94250 | M6: Patna | N6: 1 | P6: 2009 | Q6: 102000 | S6: HR | T6: 0.2 | V6: Rakesh | W6: 105000 | Y6: HR | Z6: 10.428571 | AB6: HR | AC6: 7 | AE6: HR | AF6: 427000
A7: IT | B7: 10 | C7: 56000 | D7: 0 | F7: Grand Total | G7: 50 | I7: 4-8 Years | J7: 14 | K7: 55928.571 | M7: Hyderabad | N7: 1 | P7: 2010 | Q7: 286000 | S7: IT | T7: 0 | V7: Rajesh | W7: 102000 | Y7: IT | Z7: 5.9 | AB7: IT | AC7: 10 | AE7: IT | AF7: 560000
A8: Marketing | B8: 8 | C8: 58125 | D8: 0 | I8: 9-15 Years | J8: 13 | K8: 71461.538 | M8: Jaipur | N8: 4 | P8: 2011 | Q8: 173000 | S8: Marketing | T8: 0 | V8: Mukesh | W8: 98000 | Y8: Marketing | Z8: 7 | AB8: Marketing | AC8: 8 | AE8: Marketing | AF8: 465000
A9: Operations | B9: 8 | C9: 74750 | D9: 1 | I9: Grand Total | J9: 50 | K9: 66280 | M9: Ahmedabad | N9: 1 | P9: 2012 | Q9: 283000 | S9: Operations | T9: 0.2 | V9: Deepak | W9: 95000 | Y9: Operations | Z9: 14.25 | AB9: Operations | AC9: 8 | AE9: Operations | AF9: 598000
A10: Sales | B10: 9 | C10: 66666.667 | D10: 2 | M10: Amritsar | N10: 1 | P10: 2013 | Q10: 92000 | S10: Sales | T10: 0.4 | Y10: Sales | Z10: 11.444444 | AB10: Sales | AC10: 9 | AE10: Sales | AF10: 600000
A11: Grand Total | B11: 50 | C11: 66280 | D11: 5 | M11: Bengaluru | N11: 2 | P11: 2014 | Q11: 153000 | S11: Grand Total | T11: 1 | AB11: Grand Total | AC11: 50 | AE11: Grand Total | AF11: 3314000
M12: Bhopal | N12: 2 | P12: 2015 | Q12: 312000
M13: Bilaspur | N13: 1 | P13: 2016 | Q13: 233000
M14: Chandigarh | N14: 1 | P14: 2017 | Q14: 191000
M15: Chennai | N15: 2 | P15: 2018 | Q15: 260000
M16: Dehradun | N16: 1 | P16: 2019 | Q16: 400000
M17: Gurgaon | N17: 2 | P17: 2020 | Q17: 203000
M18: Indore | N18: 3 | P18: 2021 | Q18: 287000
M19: Jodhpur | N19: 1 | P19: 2022 | Q19: 199000
M20: Kolkata | N20: 1 | P20: 2023 | Q20: 35000
M21: Lucknow | N21: 1 | P21: Grand Total | Q21: 3314000
M22: Meerut | N22: 1
M23: Mumbai | N23: 4
M24: Nagpur | N24: 1
M25: Nashik | N25: 1
M26: Noida | N26: 3
M27: Pune | N27: 5
M28: Raipur | N28: 1
M29: Surat | N29: 1
M30: Trivandrum | N30: 1
M31: Udaipur | N31: 1
M32: Grand Total | N32: 50

Sheet DASHBOARD
A1: DASHBOARD

Sheet Insights
A1: HR Analytics Dashboard Summary The organization has a total workforce of 50 employees, indicating a mid-sized and growing setup. The overall attrition rate stands at 10%, which falls within a healthy range and reflects stable employee retention. The average salary is 66,280, showing a balanced mix of mid-level and senior-level roles. The average employee experience is 10.36 years, highlighting a highly experienced and skilled workforce. Department-wise analysis shows that IT and Sales have the highest headcount, indicating a technology-driven and revenue-focused business model, while HR operates with a lean team structure. Salary distribution across departments reveals higher compensation in Finance and Sales, suggesting the presence of critical and senior positions in these functions. The gender distribution is evenly balanced with 50% male and 50% female employees, reflecting strong diversity and inclusion practices. The joining trend analysis shows periods of high hiring during business growth phases and lower hiring during economic slowdown years, demonstrating strategic workforce planning. Overall, this HR Analytics Dashboard provides management with a comprehensive view of workforce strength, stability, cost structure, experience level, diversity, and hiring trends, enabling data-driven decision-making for recruitment, retention, and compensation planning.
